//如果程序在try块外面调用hmean将无法处理异常
//try、catch、throw是成对的；
//throw函数是将函数调用序列后退，直到找到try块的函数；
#include<iostream>
double hmean(double a, double b);
int main()
{
	double x, y, z;
	std::cout << "Enter two numbers:";
	while (std::cin >> x >> y)
	{
		try { //start of try block
			z = hmean(x, y);  
		}//end of try block
		catch (const char *s)
		{//start of exception handler
			std::cout << s << std::endl;
			std::cout << "Enter a new pair of numbers: ";
			continue;
		}//end of handler
		std::cout << "Harmonic mean of" << x << " and " << y << " is " << z << std::endl;
		std::cout << "Enter next set of numbers <q to quit>: ";
	}
	std::cout << "Bye!\n";
	return 0;
}
double hmean(double a, double b)
{
	if (a == -b)
		throw"bad hmean() arguments:a=-b not alolowed";
	return 2.0*a*b / (a + b);
}
/*
Enter two numbers:3 6
Harmonic mean of3 and 6 is 4
Enter next set of numbers <q to quit>: 10 -10
bad hmean() arguments:a=-b not alolowed
Enter a new pair of numbers: 1 19
Harmonic mean of1 and 19 is 1.9
Enter next set of numbers <q to quit>: q
Bye!
*/